$ python more_decorator.py
Запись в базу данных, сетевой вызов и т.д.
При возникновении исключения попытка будет автоматически повторена.
ERROR:retry:Попытка 1/5 не удалась : (('Некоторое плохое значение',), {})
Traceback (most recent call last):
  File "more_decorator.py", line 14, in wrapper_function
    return f(*args, **kwargs)
  File "more_decorator.py", line 39, in save_to_database
    raise ValueError(arg)
ValueError: Некоторое плохое значение
Запись в базу данных, сетевой вызов и т.д.
При возникновении исключения попытка будет автоматически повторена.
